Workbook

Sheet Inputs
A1: Keytruda (PD-1 Inhibitor) – Oncology Forecast | United States
A2: Parameter | B2: Base Value | C2: YoY Growth (%) | D2: Range (Min–Max) | E2: Rationale / Notes
A3: SECTION 1 – General Parameters
A4: Product Name | B4: Keytruda | E4: Brand name of the product
A5: Class / MoA | B5: PD-1 Inhibitor | E5: Mechanism of action
A6: Indication | B6: Oncology | E6: Therapeutic indication
A7: Country | B7: United States | E7: Target market
A8: Launch Year | B8: 2026 | E8: Year of commercial launch
A9: Peak Year | B9: 2031 | E9: Year of peak sales
A10: Forecast Period | B10: 2026 – 2031 | D10: 6 years (inclusive) | E10: peak_year - launch_year + 1 = 6 years
A11: SECTION 2 – Population & Epidemiology
A12: Total Population (persons) | B12: 335000000 | C12: 0.005 | D12: 318,250,000 – 351,750,000 | E12: Total US population; 2024 census data
A13: Prevalence Rate | B13: 0.0048 | C13: 0.1 | D13: 0.0034 – 0.0062 | E13: Cancer prevalence 0.48% per GLOBOCAN 2023
A14: Diagnosis Rate | B14: 0.92 | C14: — | D14: 78% – 101% | E14: Diagnosis rate 92%; symptomatic presentation
A15: Eligibility Rate (Biomarker +) | B15: 0.68 | C15: — | D15: 51% – 78% | E15: 68% biomarker positive rate
A16: Treatment Rate | B16: 0.77 | C16: — | D16: 62% – 89% | E16: Treatment rate 77% for eligible patients
A17: SECTION 3 – Market Share Assumptions
A18: Class Share (PD-1 Inhibitors) – Peak | B18: 0.44 | C18: — | D18: 20% – 55% | E18: PD-1 Inhibitor expected 44% in target cancer segment
A19: Class Share – Starting Share | B19: 0.05 | C19: — | D19: — | E19: Starting class share at launch (Year 1)
A20: Class Share – Time to Peak (years) | B20: 5 | C20: — | D20: — | E20: S-curve adoption; 5 years from launch to peak
A21: Class Share – Curve Type | B21: S-Curve | C21: — | D21: — | E21: S-curve ramp from starting share to peak share
A22: Product Share (within class) – Peak | B22: 0.31 | C22: — | D22: 15% – 40% | E22: 31% share; benchmarking recent IO launches
A23: Product Share – Starting Share | B23: 0.03 | C23: — | D23: — | E23: Starting product share at launch (Year 1)
A24: Product Share – Time to Peak (years) | B24: 5 | C24: — | D24: — | E24: S-curve adoption; 5 years from launch to peak
A25: Product Share – Curve Type | B25: S-Curve | C25: — | D25: — | E25: S-curve ramp from starting share to peak share
A26: SECTION 4 – Pricing & Revenue Parameters
A27: Annual Cost per Patient (Gross) | B27: 185000 | C27: — | D27: $45,000 – $95,000 | E27: Annual cost $185K per oncology pricing benchmarks
A28: Discount Rate | B28: 0.22 | C28: — | D28: 15% – 30% | E28: Oncology discounts 15–22% vs primary care
A29: Net Price per Patient | B29: =B28*(1-B29) | C29: — | D29: — | E29: =Annual Cost × (1 – Discount Rate)
A30: Compliance / Persistence Rate | B30: 0.85 | C30: — | D30: — | E30: Default compliance rate (revenue_defaults)
A32: SECTION 5 – S-Curve Adoption Schedule (2026–2031)
A33: Metric | B33: 2026 | C33: 2027 | D33: 2028 | E33: 2029 | F33: 2030 | G33: 2031
A34: Class Share (PD-1 Inhibitors) | B34: 0.05 | C34: 0.1 | D34: 0.22 | E34: 0.34 | F34: 0.41 | G34: 0.44
A35: Product Share (within class) | B35: 0.03 | C35: 0.07 | D35: 0.15 | E35: 0.23 | F35: 0.28 | G35: 0.31
A37: SECTION 6 – Cell Reference Map (for Calculations sheet)
A38: Cell Ref | B38: Parameter Name | C38: Value
A39: B4 | B39: Product Name | C39: Keytruda
A40: B8 | B40: Launch Year | C40: 2026
A41: B9 | B41: Peak Year | C41: 2031
A42: B12 | B42: Base Population (persons) | C42: 335000000
...

Sheet Calculations
A1: Keytruda (PD-1 Inhibitor) – Oncology Forecast | Calculations | United States 2026–2031
A2: SECTION 1 – Input Parameters (referenced from Inputs sheet)
A3: Parameter | B3: Unit / Notes | C3: 2026 | D3: 2027 | E3: 2028 | F3: 2029 | G3: 2030 | H3: 2031
A4: Base Population | B4: persons | C4: =Inputs!B12 | D4: =C4*(1+Inputs!$C$12) | E4: =D4*(1+Inputs!$C$12) | F4: =E4*(1+Inputs!$C$12) | G4: =F4*(1+Inputs!$C$12) | H4: =G4*(1+Inputs!$C$12)
A5: Prevalence Rate | B5: rate | C5: =Inputs!B13 | D5: =C5*(1+Inputs!$C$13) | E5: =D5*(1+Inputs!$C$13) | F5: =E5*(1+Inputs!$C$13) | G5: =F5*(1+Inputs!$C$13) | H5: =G5*(1+Inputs!$C$13)
A6: Diagnosis Rate | B6: % | C6: =Inputs!$B$14 | D6: =Inputs!$B$14 | E6: =Inputs!$B$14 | F6: =Inputs!$B$14 | G6: =Inputs!$B$14 | H6: =Inputs!$B$14
A7: Eligibility Rate (Biomarker+) | B7: % | C7: =Inputs!$B$15 | D7: =Inputs!$B$15 | E7: =Inputs!$B$15 | F7: =Inputs!$B$15 | G7: =Inputs!$B$15 | H7: =Inputs!$B$15
A8: Treatment Rate | B8: % | C8: =Inputs!$B$16 | D8: =Inputs!$B$16 | E8: =Inputs!$B$16 | F8: =Inputs!$B$16 | G8: =Inputs!$B$16 | H8: =Inputs!$B$16
A9: Class Share (PD-1 Inhibitors) | B9: % | C9: =Inputs!B34 | D9: =Inputs!C34 | E9: =Inputs!D34 | F9: =Inputs!E34 | G9: =Inputs!F34 | H9: =Inputs!G34
A10: Product Share (within class) | B10: % | C10: =Inputs!B35 | D10: =Inputs!C35 | E10: =Inputs!D35 | F10: =Inputs!E35 | G10: =Inputs!F35 | H10: =Inputs!G35
A11: Annual Cost per Patient (Gross) | B11: USD | C11: =Inputs!$B$27 | D11: =Inputs!$B$27 | E11: =Inputs!$B$27 | F11: =Inputs!$B$27 | G11: =Inputs!$B$27 | H11: =Inputs!$B$27
A12: Discount Rate | B12: % | C12: =Inputs!$B$28 | D12: =Inputs!$B$28 | E12: =Inputs!$B$28 | F12: =Inputs!$B$28 | G12: =Inputs!$B$28 | H12: =Inputs!$B$28
A13: Net Price per Patient | B13: USD | C13: =C11*(1-C12) | D13: =D11*(1-D12) | E13: =E11*(1-E12) | F13: =F11*(1-F12) | G13: =G11*(1-G12) | H13: =H11*(1-H12)
A14: Compliance Rate | B14: % | C14: =Inputs!$B$30 | D14: =Inputs!$B$30 | E14: =Inputs!$B$30 | F14: =Inputs!$B$30 | G14: =Inputs!$B$30 | H14: =Inputs!$B$30
A15: SECTION 2 – Patient Funnel (Iterative Chain)
A16: Patient Funnel Metric | B16: Unit | C16: 2026 | D16: 2027 | E16: 2028 | F16: 2029 | G16: 2030 | H16: 2031
A17: Total Population | B17: persons | C17: =C4 | D17: =D4 | E17: =E4 | F17: =F4 | G17: =G4 | H17: =H4
A18: Affected Population (Prevalent) | B18: persons | C18: =C17*C5 | D18: =D17*D5 | E18: =E17*E5 | F18: =F17*F5 | G18: =G17*G5 | H18: =H17*H5
A19: Diagnosed Population | B19: persons | C19: =C18*C6 | D19: =D18*D6 | E19: =E18*E6 | F19: =F18*F6 | G19: =G18*G6 | H19: =H18*H6
A20: Eligible Population (Biomarker+) | B20: persons | C20: =C19*C7 | D20: =D19*D7 | E20: =E19*E7 | F20: =F19*F7 | G20: =G19*G7 | H20: =H19*H7
A21: Treated Population | B21: persons | C21: =C20*C8 | D21: =D20*D8 | E21: =E20*E8 | F21: =F20*F8 | G21: =G20*G8 | H21: =H20*H8
A22: In-Class Patients (PD-1 Inhibitors) | B22: persons | C22: =C21*C9 | D22: =D21*D9 | E22: =E21*E9 | F22: =F21*F9 | G22: =G21*G9 | H22: =H21*H9
A23: On-Product Patients (Keytruda) | B23: persons | C23: =C22*C10 | D23: =D22*D10 | E23: =E22*E10 | F23: =F22*F10 | G23: =G22*G10 | H23: =H22*H10
A24: SECTION 3 – Revenue Calculations
A25: Revenue Metric | B25: Unit | C25: 2026 | D25: 2027 | E25: 2028 | F25: 2029 | G25: 2030 | H25: 2031
A26: Gross Revenue | B26: USD | C26: =C23*C11 | D26: =D23*D11 | E26: =E23*E11 | F26: =F23*F11 | G26: =G23*G11 | H26: =H23*H11
A27: Net Revenue (post-discount) | B27: USD | C27: =C23*C13 | D27: =D23*D13 | E27: =E23*E13 | F27: =F23*F13 | G27: =G23*G13 | H27: =H23*H13
A28: Compliance-Adjusted Net Revenue | B28: USD | C28: =C27*C14 | D28: =D27*D14 | E28: =E27*E14 | F28: =F27*F14 | G28: =G27*G14 | H28: =H27*H14
A29: Compliance-Adjusted Net Revenue ($M) | B29: USD Millions | C29: =C28/1000000 | D29: =D28/1000000 | E29: =E28/1000000 | F29: =F28/1000000 | G29: =G28/1000000 | H29: =H28/1000000
A30: SECTION 4 – Year-over-Year Growth Metrics
A31: Growth Metric | B31: Unit | C31: 2026 | D31: 2027 | E31: 2028 | F31: 2029 | G31: 2030 | H31: 2031
A32: YoY On-Product Patient Growth | B32: % | C32: N/A | D32: =IF(C23=0,"",(D23-C23)/C23) | E32: =IF(D23=0,"",(E23-D23)/D23) | F32: =IF(E23=0,"",(F23-E23)/E23) | G32: =IF(F23=0,"",(G23-F23)/F23) | H32: =IF(G23=0,"",(H23-G23)/G23)
A33: YoY Net Revenue Growth | B33: % | C33: N/A | D33: =IF(C28=0,"",(D28-C28)/C28) | E33: =IF(D28=0,"",(E28-D28)/D28) | F33: =IF(E28=0,"",(F28-E28)/E28) | G33: =IF(F28=0,"",(G28-F28)/F28) | H33: =IF(G28=0,"",(H28-G28)/G28)
A34: SECTION 5 – Cumulative & Summary Totals
A35: Cumulative Metric | B35: Unit | C35: 2026 | D35: 2027 | E35: 2028 | F35: 2029 | G35: 2030 | H35: 2031
A36: Cumulative Net Revenue (to date) | B36: USD | C36: =C28 | D36: =C36+D28 | E36: =D36+E28 | F36: =E36+F28 | G36: =F36+G28 | H36: =G36+H28
A37: Cumulative Net Revenue ($M) | B37: USD Millions | C37: =C36/1000000 | D37: =D36/1000000 | E37: =E36/1000000 | F37: =F36/1000000 | G37: =G36/1000000 | H37: =H36/1000000

Sheet Summary
A1: KEYTRUDA (PD-1 INHIBITOR) — ONCOLOGY FORECAST SUMMARY
A2: United States | Launch: 2026 | Peak: 2031 | Forecast Period: 2026–2031
A3: SECTION 1 – Key Financial Outputs
A4: Metric | B4: Unit | C4: 2026 | D4: 2027 | E4: 2028 | F4: 2029 | G4: 2030 | H4: 2031
A5: Compliance-Adjusted Net Revenue | B5: USD | C5: =Calculations!C28 | D5: =Calculations!D28 | E5: =Calculations!E28 | F5: =Calculations!F28 | G5: =Calculations!G28 | H5: =Calculations!H28
A6: Net Revenue ($M) | B6: USD Millions | C6: =Calculations!C29 | D6: =Calculations!D29 | E6: =Calculations!E29 | F6: =Calculations!F29 | G6: =Calculations!G29 | H6: =Calculations!H29
A7: Gross Revenue | B7: USD | C7: =Calculations!C26 | D7: =Calculations!D26 | E7: =Calculations!E26 | F7: =Calculations!F26 | G7: =Calculations!G26 | H7: =Calculations!H26
A8: Net Revenue (post-discount) | B8: USD | C8: =Calculations!C27 | D8: =Calculations!D27 | E8: =Calculations!E27 | F8: =Calculations!F27 | G8: =Calculations!G27 | H8: =Calculations!H27
A9: Cumulative Net Revenue (to date) | B9: USD | C9: =Calculations!C36 | D9: =Calculations!D36 | E9: =Calculations!E36 | F9: =Calculations!F36 | G9: =Calculations!G36 | H9: =Calculations!H36
A10: Cumulative Net Revenue ($M) | B10: USD Millions | C10: =Calculations!C37 | D10: =Calculations!D37 | E10: =Calculations!E37 | F10: =Calculations!F37 | G10: =Calculations!G37 | H10: =Calculations!H37
A11: YoY Net Revenue Growth | B11: % | C11: =Calculations!C33 | D11: =Calculations!D33 | E11: =Calculations!E33 | F11: =Calculations!F33 | G11: =Calculations!G33 | H11: =Calculations!H33
A12: SECTION 2 – Patient Funnel Summary
A13: Metric | B13: Unit | C13: 2026 | D13: 2027 | E13: 2028 | F13: 2029 | G13: 2030 | H13: 2031
A14: Total Population | B14: persons | C14: =Calculations!C17 | D14: =Calculations!D17 | E14: =Calculations!E17 | F14: =Calculations!F17 | G14: =Calculations!G17 | H14: =Calculations!H17
A15: Affected Population (Prevalent) | B15: persons | C15: =Calculations!C18 | D15: =Calculations!D18 | E15: =Calculations!E18 | F15: =Calculations!F18 | G15: =Calculations!G18 | H15: =Calculations!H18
A16: Diagnosed Population | B16: persons | C16: =Calculations!C19 | D16: =Calculations!D19 | E16: =Calculations!E19 | F16: =Calculations!F19 | G16: =Calculations!G19 | H16: =Calculations!H19
A17: Eligible Population (Biomarker+) | B17: persons | C17: =Calculations!C20 | D17: =Calculations!D20 | E17: =Calculations!E20 | F17: =Calculations!F20 | G17: =Calculations!G20 | H17: =Calculations!H20
A18: Treated Population | B18: persons | C18: =Calculations!C21 | D18: =Calculations!D21 | E18: =Calculations!E21 | F18: =Calculations!F21 | G18: =Calculations!G21 | H18: =Calculations!H21
A19: In-Class Patients (PD-1 Inhibitors) | B19: persons | C19: =Calculations!C22 | D19: =Calculations!D22 | E19: =Calculations!E22 | F19: =Calculations!F22 | G19: =Calculations!G22 | H19: =Calculations!H22
A20: On-Product Patients (Keytruda) | B20: persons | C20: =Calculations!C23 | D20: =Calculations!D23 | E20: =Calculations!E23 | F20: =Calculations!F23 | G20: =Calculations!G23 | H20: =Calculations!H23
A21: YoY On-Product Patient Growth | B21: % | C21: =Calculations!C32 | D21: =Calculations!D32 | E21: =Calculations!E32 | F21: =Calculations!F32 | G21: =Calculations!G32 | H21: =Calculations!H32
A22: SECTION 3 – Market Share & Pricing Assumptions
A23: Metric | B23: Unit | C23: 2026 | D23: 2027 | E23: 2028 | F23: 2029 | G23: 2030 | H23: 2031
A24: Class Share (PD-1 Inhibitors) | B24: % | C24: =Calculations!C9 | D24: =Calculations!D9 | E24: =Calculations!E9 | F24: =Calculations!F9 | G24: =Calculations!G9 | H24: =Calculations!H9
A25: Product Share (within class) | B25: % | C25: =Calculations!C10 | D25: =Calculations!D10 | E25: =Calculations!E10 | F25: =Calculations!F10 | G25: =Calculations!G10 | H25: =Calculations!H10
A26: Net Price per Patient | B26: USD | C26: =Calculations!C13 | D26: =Calculations!D13 | E26: =Calculations!E13 | F26: =Calculations!F13 | G26: =Calculations!G13 | H26: =Calculations!H13
A27: Compliance Rate | B27: % | C27: =Calculations!C14 | D27: =Calculations!D14 | E27: =Calculations!E14 | F27: =Calculations!F14 | G27: =Calculations!G14 | H27: =Calculations!H14
A28: SECTION 4 – KPI Snapshot (Forecast Period 2026–2031)
A29: Peak Year On-Product Patients | B29: Value | C29: =Calculations!H23
A30: Peak Year Net Revenue ($M) | B30: Value | C30: =Calculations!H29
A31: Total Cumulative Net Revenue ($M) | B31: Value | C31: =Calculations!H37
A32: Peak Class Share | B32: Value | C32: =Calculations!H9
A33: Peak Product Share | B33: Value | C33: =Calculations!H10
A34: Net Price per Patient (Year 1) | B34: Value | C34: =Calculations!C13
A35: SECTION 5 – Model Notes & Key Assumptions
A36: • Forecast Period: 2026–2031 (6 years, launch year to peak year inclusive)
A37: • Patient Funnel: Population → Prevalence → Diagnosis (92%) → Eligibility/Biomarker+ (68%) → Treatment (77%) → Class Share (S-curve) → Product Share (S-curve)
A38: • Class Share: S-curve ramp from 5% (2026) to 44% (2031); Product Share: S-curve from 3% (2026) to 31% (2031)
A39: • Pricing: Gross $185,000/patient; Discount 22%; Net ~$144,300/patient; Compliance 85%
A40: • Population Growth: 0.5% YoY; Prevalence Growth: 10% YoY (GLOBOCAN 2023 basis)
...
